Workbook

Sheet quad_codici
A1: codice | B1: chiamata | C1: da dove | D1: riferimento | E1: step
A2: copia_audio_non_disp.bat | B2: util | C2: crea per la pagina i file audio nelle diverse lingue non disponibile | E2: =_xlfn.XLOOKUP(D2, decodifica!$B:$B, decodifica!$C:$C, "Non trovato") -> 0
A3: caricamento_testi.bat | B3: manuale | C3: Creazione di caricamento_testi_{lang}_paginaxy.bat (template) | E3: =_xlfn.XLOOKUP(D3, decodifica!$B:$B, decodifica!$C:$C, "Non trovato") -> 0
A4: extract_images.py | C4: Disamina del documento word paginaxy.docx | E4: =_xlfn.XLOOKUP(D4, decodifica!$B:$B, decodifica!$C:$C, "Non trovato") -> 0
A5: html_fragment_cleaner.py | C5: Disamina del documento word paginaxy.docx | E5: =_xlfn.XLOOKUP(D5, decodifica!$B:$B, decodifica!$C:$C, "Non trovato") -> 0
A6: post_process_html.py | C6: Disamina del documento word paginaxy.docx | E6: =_xlfn.XLOOKUP(D6, decodifica!$B:$B, decodifica!$C:$C, "Non trovato") -> 0
A7: collect_all_code.py | B7: util | C7: genera un file di testo con tutti i codici '.py', '.bat', '.js', '.html', '.css', '.json' | E7: =_xlfn.XLOOKUP(D7, decodifica!$B:$B, decodifica!$C:$C, "Non trovato") -> 0
A8: cerca_nel_json.py | B8: util | C8: nel file texts.json visualizza un blocco della pagina per tutte le lingue | E8: =_xlfn.XLOOKUP(D8, decodifica!$B:$B, decodifica!$C:$C, "Non trovato") -> 0
A9: pulizia_html.py | B9: util | C9: Rimuove i tag <div class="main-text-content"> nidificati in eccesso, lasciandone solo uno esterno o rimuovendoli del tutto se preferito. | D9: tit_Disamina_del_materiale_ricevuto | E9: =_xlfn.XLOOKUP(D9, decodifica!$B:$B, decodifica!$C:$C, "Non trovato") -> 7
A10: process_all_pages.py | B10: util | C10: alternativa per la conversione docx a html | D10: tit_Disamina_del_materiale_ricevuto | E10: =_xlfn.XLOOKUP(D10, decodifica!$B:$B, decodifica!$C:$C, "Non trovato") -> 7
A11: convert_docx_to_html.bat | B11: manuale | C11: conversione python da docx a html | D11: tit_Disamina_del_documento_word_paginaxy | E11: =_xlfn.XLOOKUP(D11, decodifica!$B:$B, decodifica!$C:$C, "Non trovato") -> 9
A12: convert_docx_to_html.py | B12: manuale | C12: conversione python da docx a html | D12: tit_Disamina_del_documento_word_paginaxy | E12: =_xlfn.XLOOKUP(D12, decodifica!$B:$B, decodifica!$C:$C, "Non trovato") -> 9
A13: convert_page.bat | B13: manuale | C13: Disamina del documento word paginaxy.docx | D13: tit_Disamina_del_documento_word_paginaxy | E13: =_xlfn.XLOOKUP(D13, decodifica!$B:$B, decodifica!$C:$C, "Non trovato") -> 9
A14: split_and_update_content.py | C14: Disamina del documento word paginaxy.docx | D14: tit_Disamina_del_documento_word_paginaxy | E14: =_xlfn.XLOOKUP(D14, decodifica!$B:$B, decodifica!$C:$C, "Non trovato") -> 9
A15: sync_config.py | C15: Disamina del documento word paginaxy.docx | D15: tit_Disamina_del_documento_word_paginaxy | E15: =_xlfn.XLOOKUP(D15, decodifica!$B:$B, decodifica!$C:$C, "Non trovato") -> 9
A16: add_bsmariamaggiore.bat | C16: generato da create_newpage.py | D16: tit_Creazione_dello_script_add_paginaxy_ | E16: =_xlfn.XLOOKUP(D16, decodifica!$B:$B, decodifica!$C:$C, "Non trovato") -> 10
A17: add_cavaticcio.bat | C17: generato da create_newpage.py | D17: tit_Creazione_dello_script_add_paginaxy_ | E17: =_xlfn.XLOOKUP(D17, decodifica!$B:$B, decodifica!$C:$C, "Non trovato") -> 10
A18: add_chiesasancarlo.bat | C18: generato da create_newpage.py | D18: tit_Creazione_dello_script_add_paginaxy_ | E18: =_xlfn.XLOOKUP(D18, decodifica!$B:$B, decodifica!$C:$C, "Non trovato") -> 10
A19: add_pittoricarracci.bat | C19: generato da create_newpage.py | D19: tit_Creazione_dello_script_add_paginaxy_ | E19: =_xlfn.XLOOKUP(D19, decodifica!$B:$B, decodifica!$C:$C, "Non trovato") -> 10
A20: add_pugliole.bat | C20: generato da create_newpage.py | D20: tit_Creazione_dello_script_add_paginaxy_ | E20: =_xlfn.XLOOKUP(D20, decodifica!$B:$B, decodifica!$C:$C, "Non trovato") -> 10
A21: extract_gps.py | C21: Identificazione delle coordinate GPS | D21: tit_Identificazione_delle_coordinate_GPS | E21: =_xlfn.XLOOKUP(D21, decodifica!$B:$B, decodifica!$C:$C, "Non trovato") -> 11
A22: get_coords_from_img.bat | C22: Identificazione delle coordinate GPS | D22: tit_Identificazione_delle_coordinate_GPS | E22: =_xlfn.XLOOKUP(D22, decodifica!$B:$B, decodifica!$C:$C, "Non trovato") -> 11
A23: extract_config_poi.py | B23: util | C23: Gestione del pois_config.json | D23: tit_Gestione_del_pois_config_json | E23: =_xlfn.XLOOKUP(D23, decodifica!$B:$B, decodifica!$C:$C, "Non trovato") -> 13
A24: load_config_poi.py | B24: util | C24: Gestione del pois_config.json | D24: tit_Gestione_del_pois_config_json | E24: =_xlfn.XLOOKUP(D24, decodifica!$B:$B, decodifica!$C:$C, "Non trovato") -> 13
A25: sync_nav_from_config.py | C25: Gestione del pois_config.json Recupero da pois_config.json con sync_nav_from_config.py | D25: tit_Gestione_del_pois_config_json | E25: =_xlfn.XLOOKUP(D25, decodifica!$B:$B, decodifica!$C:$C, "Non trovato") -> 13
A26: %UTILITIES%\salvag.bat | C26: Crea e modifica add_paginaxy.bat (NEWS version) | D26: tit_Crea_e_modifica_add_paginaxy_bat_NEW | E26: =_xlfn.XLOOKUP(D26, decodifica!$B:$B, decodifica!$C:$C, "Non trovato") -> 14
A27: add_newpage.bat | C27: Crea e modifica add_paginaxy.bat (NEWS version) | D27: tit_Crea_e_modifica_add_paginaxy_bat_NEW | E27: =_xlfn.XLOOKUP(D27, decodifica!$B:$B, decodifica!$C:$C, "Non trovato") -> 14
A28: add_page.py | C28: Crea e modifica add_paginaxy.bat (NEWS version) | D28: tit_Crea_e_modifica_add_paginaxy_bat_NEW | E28: =_xlfn.XLOOKUP(D28, decodifica!$B:$B, decodifica!$C:$C, "Non trovato") -> 14
A29: create_newpage.py | B29: manuale | C29: Crea e modifica add_paginaxy.bat (NEWS version) | D29: tit_Crea_e_modifica_add_paginaxy_bat_NEW | E29: =_xlfn.XLOOKUP(D29, decodifica!$B:$B, decodifica!$C:$C, "Non trovato") -> 14
A30: salvag.bat | B30: util | C30: richiamato da add_pagina.bat - fa copia del file in Documents\salvataggi_github con la data_ora | D30: tit_Crea_e_modifica_add_paginaxy_bat_NEW | E30: =_xlfn.XLOOKUP(D30, decodifica!$B:$B, decodifica!$C:$C, "Non trovato") -> 14
A31: snapshot_sito.bat | B31: util | C31: salvataggio del sito (backup.bat) | D31: tit_Crea_e_modifica_add_paginaxy_bat_NEW | E31: =_xlfn.XLOOKUP(D31, decodifica!$B:$B, decodifica!$C:$C, "Non trovato") -> 14
A32: extract_nav_to_json.py | C32: Gestione della lista dei nav nei files HTML | D32: tit_Gestione_della_lista_dei_nav_nei_fil | E32: =_xlfn.XLOOKUP(D32, decodifica!$B:$B, decodifica!$C:$C, "Non trovato") -> 16
A33: update_html_from_json.py | C33: Gestione della lista dei nav nei files HTML | D33: tit_Gestione_della_lista_dei_nav_nei_fil | E33: =_xlfn.XLOOKUP(D33, decodifica!$B:$B, decodifica!$C:$C, "Non trovato") -> 16
A34: cleanup_fragments.py | B34: util | C34: Esegue la pulizia dei file obsoleti dopo il processo di dimissione. Rimuove file audio .mp3 e frammenti .html (maintext). | D34: tit_Dopo_aver_eseguito_add_paginaxy_bat | E34: =_xlfn.XLOOKUP(D34, decodifica!$B:$B, decodifica!$C:$C, "Non trovato") -> 18
A35: dimissione_procedura.bat | C35: generato da create_newpage.py | D35: tit_Dopo_aver_eseguito_add_paginaxy_bat | E35: =_xlfn.XLOOKUP(D35, decodifica!$B:$B, decodifica!$C:$C, "Non trovato") -> 18
A36: go_dimissione.py | B36: manuale | C36: python : elimina tutti i files ed i puntamenti della pagina da dismettere da sito | D36: tit_Dopo_aver_eseguito_add_paginaxy_bat | E36: =_xlfn.XLOOKUP(D36, decodifica!$B:$B, decodifica!$C:$C, "Non trovato") -> 18
A37: update_json_key.py | B37: util | C37: aggiorna i texts.json a partire dalla directory text_files | D37: tit_Caricamento_dei_testi_dinamici_scrip | E37: =_xlfn.XLOOKUP(D37, decodifica!$B:$B, decodifica!$C:$C, "Non trovato") -> 19
A38: key_synchronization.py | B38: util | C38: Caricamento dei testi dinamici | D38: tit_Caricamento_dei_testi_dinamici_scrip | E38: =_xlfn.XLOOKUP(D38, decodifica!$B:$B, decodifica!$C:$C, "Non trovato") -> 19
A39: esegui_all_update_json.bat | C39: Caricamento dei testi dinamici: script update_json.bat | D39: tit_Caricamento_dei_testi_dinamici_scrip | E39: =_xlfn.XLOOKUP(D39, decodifica!$B:$B, decodifica!$C:$C, "Non trovato") -> 19
A40: json_updater.py | C40: Caricamento dei testi dinamici: script update_json.bat | D40: tit_Caricamento_dei_testi_dinamici_scrip | E40: =_xlfn.XLOOKUP(D40, decodifica!$B:$B, decodifica!$C:$C, "Non trovato") -> 19
...

Sheet decodifica
A1: Come creare una pagina del sito Paginaxy | B1: tit_Come_creare_una_pagina_del_sito_Pagi | C1: 1
A2: Recupero informazioni ed immagini | B2: tit_Recupero_informazioni_ed_immagini | C2: 2
A3: Processo di creazione della pagina | B3: tit_Processo_di_creazione_della_pagina | C3: 3
A4: Salvataggio e Ripristino del sito | B4: tit_Salvataggio_e_Ripristino_del_sito | C4: 4
A5: La struttura del sito | B5: tit_La_struttura_del_sito | C5: 5
A6: Disamina del materiale ricevuto | B6: tit_Disamina_del_materiale_ricevuto | C6: 7
A7: Considerazione sul tipo di immagini e di testi nella struttura del sito. | B7: tit_Considerazione_sul_tipo_di_immagini_ | C7: 8
A8: Disamina del documento word paginaxy.docx | B8: tit_Disamina_del_documento_word_paginaxy | C8: 9
A9: Creazione dello script add_paginaxy.bat | B9: tit_Creazione_dello_script_add_paginaxy_ | C9: 10
A10: Identificazione delle coordinate GPS | B10: tit_Identificazione_delle_coordinate_GPS | C10: 11
A11: Creazione dell’audio della pagina | B11: tit_Creazione_dell_audio_della_pagina | C11: 12
A12: Gestione del pois_config.json | B12: tit_Gestione_del_pois_config_json | C12: 13
... A22: I programmi coinvolti | B22: tit_I_programmi_coinvolti | C22: 23
